<?xml version="1.0" encoding="utf-8"?>
<!-- This URDF was automatically created by SolidWorks to URDF Exporter! Originally created by Stephen Brawner (brawner@gmail.com) 
     Commit Version: 1.6.0-4-g7f85cfe  Build Version: 1.6.7995.38578
     For more information, please see http://wiki.ros.org/sw_urdf_exporter -->
<robot
  name="irobot">
  <link
    name="base_link">
    <inertial>
      <origin
        xyz="6.2317E-05 9.6607E-10 0.4314"
        rpy="0 0 0" />
      <mass
        value="8.9781" />
      <inertia
        ixx="0.56562"
        ixy="5.7133E-09"
        ixz="-4.1028E-06"
        iyy="0.5726"
        iyz="-1.9413E-10"
        izz="0.077833" />
    </inertial>
    <visual>
      <origin
        xyz="0 0 0"
        rpy="0 0 0" />
      <geometry>
        <mesh
          filename="package://irobot_description/meshes/base_link.STL" />
      </geometry>
      <material
        name="">
        <color
          rgba="0.75294 0.75294 0.75294 1" />
      </material>
    </visual>
    <collision>
      <origin
        xyz="0 0 0"
        rpy="0 0 0" />
      <geometry>
        <mesh
          filename="package://irobot_description/meshes/base_link.STL" />
      </geometry>
    </collision>
  </link>
  <link
    name="link1_R">
    <inertial>
      <origin
        xyz="2.5175E-07 0.0043759 -0.02835"
        rpy="0 0 0" />
      <mass
        value="0.51694" />
      <inertia
        ixx="0.00018144"
        ixy="-2.7613E-09"
        ixz="1.0578E-10"
        iyy="0.00013224"
        iyz="-1.4511E-05"
        izz="0.00015609" />
    </inertial>
    <visual>
      <origin
        xyz="0 0 0"
        rpy="0 0 0" />
      <geometry>
        <mesh
          filename="package://irobot_description/meshes/link1_R.STL" />
      </geometry>
      <material
        name="">
        <color
          rgba="0.75294 0.75294 0.75294 1" />
      </material>
    </visual>
    <collision>
      <origin
        xyz="0 0 0"
        rpy="0 0 0" />
      <geometry>
        <mesh
          filename="package://irobot_description/meshes/link1_R.STL" />
      </geometry>
    </collision>
  </link>
  <joint
    name="joint1_R"
    type="revolute">
    <origin
      xyz="0 -0.16 1.35"
      rpy="1.5708 -1.5708 0" />
    <parent
      link="base_link" />
    <child
      link="link1_R" />
    <axis
      xyz="0 0 1" />
    <limit
      lower="-3"
      upper="3"
      effort="7"
      velocity="5" />
  </joint>
  <link
    name="link2_R">
    <inertial>
      <origin
        xyz="0.0019345 0.022847 -0.010269"
        rpy="0 0 0" />
      <mass
        value="0.21541" />
      <inertia
        ixx="0.00031567"
        ixy="-4.1881E-06"
        ixz="2.9784E-06"
        iyy="0.00025671"
        iyz="3.424E-05"
        izz="0.00021738" />
    </inertial>
    <visual>
      <origin
        xyz="0 0 0"
        rpy="0 0 0" />
      <geometry>
        <mesh
          filename="package://irobot_description/meshes/link2_R.STL" />
      </geometry>
      <material
        name="">
        <color
          rgba="0.75294 0.75294 0.75294 1" />
      </material>
    </visual>
    <collision>
      <origin
        xyz="0 0 0"
        rpy="0 0 0" />
      <geometry>
        <mesh
          filename="package://irobot_description/meshes/link2_R.STL" />
      </geometry>
    </collision>
  </link>
  <joint
    name="joint2_R"
    type="revolute">
    <origin
      xyz="0 0 0"
      rpy="1.5708 -1.5708 0" />
    <parent
      link="link1_R" />
    <child
      link="link2_R" />
    <axis
      xyz="0 0 -1" />
    <limit
      lower="-3"
      upper="3"
      effort="7"
      velocity="5" />
  </joint>
  <link
    name="link3_R">
    <inertial>
      <origin
        xyz="3.9458E-05 0.0034161 0.09448"
        rpy="0 0 0" />
      <mass
        value="0.83206" />
      <inertia
        ixx="0.0014354"
        ixy="1.2737E-06"
        ixz="1.3438E-06"
        iyy="0.0014359"
        iyz="-2.5463E-05"
        izz="0.00055691" />
    </inertial>
    <visual>
      <origin
        xyz="0 0 0"
        rpy="0 0 0" />
      <geometry>
        <mesh
          filename="package://irobot_description/meshes/link3_R.STL" />
      </geometry>
      <material
        name="">
        <color
          rgba="0.75294 0.75294 0.75294 1" />
      </material>
    </visual>
    <collision>
      <origin
        xyz="0 0 0"
        rpy="0 0 0" />
      <geometry>
        <mesh
          filename="package://irobot_description/meshes/link3_R.STL" />
      </geometry>
    </collision>
  </link>
  <joint
    name="joint3_R"
    type="revolute">
    <origin
      xyz="0 0.27 0"
      rpy="1.5708 -1.5708 0" />
    <parent
      link="link2_R" />
    <child
      link="link3_R" />
    <axis
      xyz="0 0 1" />
    <limit
      lower="-3"
      upper="3"
      effort="10"
      velocity="5" />
  </joint>
  <link
    name="link4_R">
    <inertial>
      <origin
        xyz="0.0044083 0.028826 0.0033052"
        rpy="0 0 0" />
      <mass
        value="0.13287" />
      <inertia
        ixx="0.00019138"
        ixy="3.311E-07"
        ixz="-3.4688E-06"
        iyy="0.00016001"
        iyz="-2.3075E-05"
        izz="0.00011635" />
    </inertial>
    <visual>
      <origin
        xyz="0 0 0"
        rpy="0 0 0" />
      <geometry>
        <mesh
          filename="package://irobot_description/meshes/link4_R.STL" />
      </geometry>
      <material
        name="">
        <color
          rgba="0.75294 0.75294 0.75294 1" />
      </material>
    </visual>
    <collision>
      <origin
        xyz="0 0 0"
        rpy="0 0 0" />
      <geometry>
        <mesh
          filename="package://irobot_description/meshes/link4_R.STL" />
      </geometry>
    </collision>
  </link>
  <joint
    name="joint4_R"
    type="revolute">
    <origin
      xyz="0 0 0"
      rpy="1.5708 1.5708 0" />
    <parent
      link="link3_R" />
    <child
      link="link4_R" />
    <axis
      xyz="0 0 -1" />
    <limit
      lower="-3"
      upper="3"
      effort="10"
      velocity="5" />
  </joint>
  <link
    name="link5_R">
    <inertial>
      <origin
        xyz="2.5006E-06 -0.0041663 -0.094382"
        rpy="0 0 0" />
      <mass
        value="0.64819" />
      <inertia
        ixx="0.00073816"
        ixy="7.1837E-08"
        ixz="-1.238E-07"
        iyy="0.0006904"
        iyz="7.2492E-06"
        izz="0.00022909" />
    </inertial>
    <visual>
      <origin
        xyz="0 0 0"
        rpy="0 0 0" />
      <geometry>
        <mesh
          filename="package://irobot_description/meshes/link5_R.STL" />
      </geometry>
      <material
        name="">
        <color
          rgba="0.75294 0.75294 0.75294 1" />
      </material>
    </visual>
    <collision>
      <origin
        xyz="0 0 0"
        rpy="0 0 0" />
      <geometry>
        <mesh
          filename="package://irobot_description/meshes/link5_R.STL" />
      </geometry>
    </collision>
  </link>
  <joint
    name="joint5_R"
    type="revolute">
    <origin
      xyz="0 0.24 0"
      rpy="-1.5708 -1.5708 0" />
    <parent
      link="link4_R" />
    <child
      link="link5_R" />
    <axis
      xyz="0 0 1" />
    <limit
      lower="-3"
      upper="3"
      effort="6"
      velocity="3" />
  </joint>
  <link
    name="link6_R">
    <inertial>
      <origin
        xyz="4.2294E-08 0.0117 -0.00098129"
        rpy="0 0 0" />
      <mass
        value="0.289432" />
      <inertia
        ixx="3.7271E-05"
        ixy="-2.4071E-11"
        ixz="9.755E-11"
        iyy="3.4392E-05"
        iyz="-7.3586E-07"
        izz="1.847E-05" />
    </inertial>
    <visual>
      <origin
        xyz="0 0 0"
        rpy="0 0 0" />
      <geometry>
        <mesh
          filename="package://irobot_description/meshes/link6_R.STL" />
      </geometry>
      <material
        name="">
        <color
          rgba="0.75294 0.75294 0.75294 1" />
      </material>
    </visual>
    <collision>
      <origin
        xyz="0 0 0"
        rpy="0 0 0" />
      <geometry>
        <mesh
          filename="package://irobot_description/meshes/link6_R.STL" />
      </geometry>
    </collision>
  </link>
  <joint
    name="joint6_R"
    type="revolute">
    <origin
      xyz="0 0 0"
      rpy="1.5708 0 0" />
    <parent
      link="link5_R" />
    <child
      link="link6_R" />
    <axis
      xyz="0 0 -1" />
    <limit
      lower="-3"
      upper="3"
      effort="6"
      velocity="3" />
  </joint>
  <link
    name="link7_R">
    <inertial>
      <origin
        xyz="-0.0058253 0.0069024 0.071501"
        rpy="0 0 0" />
      <mass
        value="0.328683" />
      <inertia
        ixx="0.00011346"
        ixy="-4.179E-06"
        ixz="1.0743E-05"
        iyy="8.4473E-05"
        iyz="-1.4833E-06"
        izz="0.00011977" />
    </inertial>
    <visual>
      <origin
        xyz="0 0 0"
        rpy="0 0 0" />
      <geometry>
        <mesh
          filename="package://irobot_description/meshes/link7_R.STL" />
      </geometry>
      <material
        name="">
        <color
          rgba="0.75294 0.75294 0.75294 1" />
      </material>
    </visual>
    <collision>
      <origin
        xyz="0 0 0"
        rpy="0 0 0" />
      <geometry>
        <mesh
          filename="package://irobot_description/meshes/link7_R.STL" />
      </geometry>
    </collision>
  </link>
  <joint
    name="joint7_R"
    type="revolute">
    <origin
      xyz="0 0 0"
      rpy="-1.5708 0 0" />
    <parent
      link="link6_R" />
    <child
      link="link7_R" />
    <axis
      xyz="0 0 -1" />
    <limit
      lower="-3"
      upper="3"
      effort="6"
      velocity="3" />
  </joint>
  <link
    name="link_clip1_R">
    <inertial>
      <origin
        xyz="0.035706 0.021577 -3.2549E-07"
        rpy="0 0 0" />
      <mass
        value="0.046425" />
      <inertia
        ixx="6.3697E-05"
        ixy="-1.5504E-05"
        ixz="6.7385E-10"
        iyy="9.3082E-05"
        iyz="1.1726E-10"
        izz="5.1671E-05" />
    </inertial>
    <visual>
      <origin
        xyz="0 0 0"
        rpy="0 0 0" />
      <geometry>
        <mesh
          filename="package://irobot_description/meshes/link_clip1_R.STL" />
      </geometry>
      <material
        name="">
        <color
          rgba="0.69804 0.69804 0.69804 1" />
      </material>
    </visual>
    <collision>
      <origin
        xyz="0 0 0"
        rpy="0 0 0" />
      <geometry>
        <mesh
          filename="package://irobot_description/meshes/link_clip1_R.STL" />
      </geometry>
    </collision>
  </link>
  <joint
    name="joint_clip1_R"
    type="revolute">
    <origin
      xyz="-0.018 0 0.077"
      rpy="1.5708 -1.5708 0" />
    <parent
      link="link7_R" />
    <child
      link="link_clip1_R" />
    <axis
      xyz="0 0 1" />
    <limit
      lower="-3"
      upper="3"
      effort="6"
      velocity="3" />
  </joint>
  <link
    name="link_clip2_R">
    <inertial>
      <origin
        xyz="0.036517 -0.020929 0.0010504"
        rpy="0 0 0" />
      <mass
        value="0.049325" />
      <inertia
        ixx="6.9459E-05"
        ixy="1.6614E-05"
        ixz="1.8896E-06"
        iyy="0.00010403"
        iyz="-1.0839E-06"
        izz="5.7557E-05" />
    </inertial>
    <visual>
      <origin
        xyz="0 0 0"
        rpy="0 0 0" />
      <geometry>
        <mesh
          filename="package://irobot_description/meshes/link_clip2_R.STL" />
      </geometry>
      <material
        name="">
        <color
          rgba="0.69804 0.69804 0.69804 1" />
      </material>
    </visual>
    <collision>
      <origin
        xyz="0 0 0"
        rpy="0 0 0" />
      <geometry>
        <mesh
          filename="package://irobot_description/meshes/link_clip2_R.STL" />
      </geometry>
    </collision>
  </link>
  <joint
    name="joint_clip2_R"
    type="revolute">
    <origin
      xyz="0.018 0 0.077"
      rpy="1.5708 -1.5708 0" />
    <parent
      link="link7_R" />
    <child
      link="link_clip2_R" />
    <axis
      xyz="0 0 1" />
    <limit
      lower="-3"
      upper="3"
      effort="6"
      velocity="3" />
  </joint>
  <link
    name="link1_L">
    <inertial>
      <origin
        xyz="-2.5175E-07 0.0043759 0.02835"
        rpy="0 0 0" />
      <mass
        value="0.51694" />
      <inertia
        ixx="0.00018144"
        ixy="2.7613E-09"
        ixz="1.0578E-10"
        iyy="0.00013224"
        iyz="1.4511E-05"
        izz="0.00015609" />
    </inertial>
    <visual>
      <origin
        xyz="0 0 0"
        rpy="0 0 0" />
      <geometry>
        <mesh
          filename="package://irobot_description/meshes/link1_L.STL" />
      </geometry>
      <material
        name="">
        <color
          rgba="0.75294 0.75294 0.75294 1" />
      </material>
    </visual>
    <collision>
      <origin
        xyz="0 0 0"
        rpy="0 0 0" />
      <geometry>
        <mesh
          filename="package://irobot_description/meshes/link1_L.STL" />
      </geometry>
    </collision>
  </link>
  <joint
    name="joint1_L"
    type="revolute">
    <origin
      xyz="0 0.16 1.35"
      rpy="1.5708 -1.5708 0" />
    <parent
      link="base_link" />
    <child
      link="link1_L" />
    <axis
      xyz="0 0 1" />
    <limit
      lower="-3"
      upper="3"
      effort="7"
      velocity="5" />
  </joint>
  <link
    name="link2_L">
    <inertial>
      <origin
        xyz="0.0019344708070379 -0.0228474645182375 0.0102694951191551"
        rpy="0 0 0" />
      <mass
        value="0.215408647409358" />
      <inertia
        ixx="0.000315668257840379"
        ixy="4.18810744279108E-06"
        ixz="-2.97840448987141E-06"
        iyy="0.00025670772779746"
        iyz="3.42397132498776E-05"
        izz="0.000217377576079757" />
    </inertial>
    <visual>
      <origin
        xyz="0 0 0"
        rpy="0 0 0" />
      <geometry>
        <mesh
          filename="package://irobot_description/meshes/link2_L.STL" />
      </geometry>
      <material
        name="">
        <color
          rgba="0.752941176470588 0.752941176470588 0.752941176470588 1" />
      </material>
    </visual>
    <collision>
      <origin
        xyz="0 0 0"
        rpy="0 0 0" />
      <geometry>
        <mesh
          filename="package://irobot_description/meshes/link2_L.STL" />
      </geometry>
    </collision>
  </link>
  <joint
    name="joint2_L"
    type="revolute">
    <origin
      xyz="0 0 0"
      rpy="-1.5708 -1.5708 0" />
    <parent
      link="link1_L" />
    <child
      link="link2_L" />
    <axis
      xyz="0 0 1" />
    <limit
      lower="-3"
      upper="3"
      effort="7"
      velocity="5" />
  </joint>
  <link
    name="link3_L">
    <inertial>
      <origin
        xyz="3.9458E-05 0.0034161 0.09448"
        rpy="0 0 0" />
      <mass
        value="0.83206" />
      <inertia
        ixx="0.0014354"
        ixy="1.2737E-06"
        ixz="1.3438E-06"
        iyy="0.0014359"
        iyz="-2.5463E-05"
        izz="0.00055691" />
    </inertial>
    <visual>
      <origin
        xyz="0 0 0"
        rpy="0 0 0" />
      <geometry>
        <mesh
          filename="package://irobot_description/meshes/link3_L.STL" />
      </geometry>
      <material
        name="">
        <color
          rgba="0.75294 0.75294 0.75294 1" />
      </material>
    </visual>
    <collision>
      <origin
        xyz="0 0 0"
        rpy="0 0 0" />
      <geometry>
        <mesh
          filename="package://irobot_description/meshes/link3_L.STL" />
      </geometry>
    </collision>
  </link>
  <joint
    name="joint3_L"
    type="revolute">
    <origin
      xyz="0 -0.27 0"
      rpy="-1.5708 1.5708 0" />
    <parent
      link="link2_L" />
    <child
      link="link3_L" />
    <axis
      xyz="0 0 1" />
    <limit
      lower="-3"
      upper="3"
      effort="10"
      velocity="5" />
  </joint>
  <link
    name="link4_L">
    <inertial>
      <origin
        xyz="-0.0044114 0.028827 0.0032962"
        rpy="0 0 0" />
      <mass
        value="0.13285" />
      <inertia
        ixx="0.00019137"
        ixy="-3.3185E-07"
        ixz="3.472E-06"
        iyy="0.00016"
        iyz="-2.3076E-05"
        izz="0.00011635" />
    </inertial>
    <visual>
      <origin
        xyz="0 0 0"
        rpy="0 0 0" />
      <geometry>
        <mesh
          filename="package://irobot_description/meshes/link4_L.STL" />
      </geometry>
      <material
        name="">
        <color
          rgba="0.75294 0.75294 0.75294 1" />
      </material>
    </visual>
    <collision>
      <origin
        xyz="0 0 0"
        rpy="0 0 0" />
      <geometry>
        <mesh
          filename="package://irobot_description/meshes/link4_L.STL" />
      </geometry>
    </collision>
  </link>
  <joint
    name="joint4_L"
    type="revolute">
    <origin
      xyz="0 0 0"
      rpy="1.5708 1.5708 0" />
    <parent
      link="link3_L" />
    <child
      link="link4_L" />
    <axis
      xyz="0 0 1" />
    <limit
      lower="-3"
      upper="3"
      effort="10"
      velocity="5" />
  </joint>
  <link
    name="link5_L">
    <inertial>
      <origin
        xyz="2.4481E-06 -0.0041663 -0.094382"
        rpy="0 0 0" />
      <mass
        value="0.64819" />
      <inertia
        ixx="0.00073816"
        ixy="7.2309E-08"
        ixz="-1.2242E-07"
        iyy="0.0006904"
        iyz="7.2483E-06"
        izz="0.00022909" />
    </inertial>
    <visual>
      <origin
        xyz="0 0 0"
        rpy="0 0 0" />
      <geometry>
        <mesh
          filename="package://irobot_description/meshes/link5_L.STL" />
      </geometry>
      <material
        name="">
        <color
          rgba="0.75294 0.75294 0.75294 1" />
      </material>
    </visual>
    <collision>
      <origin
        xyz="0 0 0"
        rpy="0 0 0" />
      <geometry>
        <mesh
          filename="package://irobot_description/meshes/link5_L.STL" />
      </geometry>
    </collision>
  </link>
  <joint
    name="joint5_L"
    type="revolute">
    <origin
      xyz="0 0.24 0"
      rpy="-1.5708 -1.5708 0" />
    <parent
      link="link4_L" />
    <child
      link="link5_L" />
    <axis
      xyz="0 0 1" />
    <limit
      lower="-3"
      upper="3"
      effort="6"
      velocity="3" />
  </joint>
  <link
    name="link6_L">
    <inertial>
      <origin
        xyz="4.2294E-08 0.0117 -0.00098129"
        rpy="0 0 0" />
      <mass
        value="0.289432" />
      <inertia
        ixx="3.7271E-05"
        ixy="-2.4071E-11"
        ixz="9.755E-11"
        iyy="3.4392E-05"
        iyz="-7.3586E-07"
        izz="1.847E-05" />
    </inertial>
    <visual>
      <origin
        xyz="0 0 0"
        rpy="0 0 0" />
      <geometry>
        <mesh
          filename="package://irobot_description/meshes/link6_L.STL" />
      </geometry>
      <material
        name="">
        <color
          rgba="0.75294 0.75294 0.75294 1" />
      </material>
    </visual>
    <collision>
      <origin
        xyz="0 0 0"
        rpy="0 0 0" />
      <geometry>
        <mesh
          filename="package://irobot_description/meshes/link6_L.STL" />
      </geometry>
    </collision>
  </link>
  <joint
    name="joint6_L"
    type="revolute">
    <origin
      xyz="0 -0.0005 0"
      rpy="1.5708 0 0" />
    <parent
      link="link5_L" />
    <child
      link="link6_L" />
    <axis
      xyz="0 0 -1" />
    <limit
      lower="-3"
      upper="3"
      effort="6"
      velocity="3" />
  </joint>
  <link
    name="link7_L">
    <inertial>
      <origin
        xyz="0.00607123167086257 0.00749976634484106 0.0716117472500631"
        rpy="0 0 0" />
      <mass
        value="0.33071915360441" />
      <inertia
        ixx="0.000113510051760032"
        ixy="4.17892157581446E-06"
        ixz="-1.07431371374432E-05"
        iyy="8.45678724975597E-05"
        iyz="-1.4836781168221E-06"
        izz="0.000119822264164082" />
    </inertial>
    <visual>
      <origin
        xyz="0 0 0"
        rpy="0 0 0" />
      <geometry>
        <mesh
          filename="package://irobot_description/meshes/link7_L.STL" />
      </geometry>
      <material
        name="">
        <color
          rgba="0.752941176470588 0.752941176470588 0.752941176470588 1" />
      </material>
    </visual>
    <collision>
      <origin
        xyz="0 0 0"
        rpy="0 0 0" />
      <geometry>
        <mesh
          filename="package://irobot_description/meshes/link7_L.STL" />
      </geometry>
    </collision>
  </link>
  <joint
    name="joint7_L"
    type="revolute">
    <origin
      xyz="0 0 0"
      rpy="-1.5708 0 0" />
    <parent
      link="link6_L" />
    <child
      link="link7_L" />
    <axis
      xyz="0 0 -1" />
    <limit
      lower="-3"
      upper="3"
      effort="6"
      velocity="3" />
  </joint>
  <link
    name="link_clip1_L">
    <inertial>
      <origin
        xyz="0.0357062080180098 -0.0215773738573617 3.25486620766924E-07"
        rpy="0 0 0" />
      <mass
        value="0.0464245731590219" />
      <inertia
        ixx="6.36974773430474E-05"
        ixy="1.55036216537389E-05"
        ixz="-6.73848882791432E-10"
        iyy="9.30815103696084E-05"
        iyz="1.17258365002596E-10"
        izz="5.16706792509683E-05" />
    </inertial>
    <visual>
      <origin
        xyz="0 0 0"
        rpy="0 0 0" />
      <geometry>
        <mesh
          filename="package://irobot_description/meshes/link_clip1_L.STL" />
      </geometry>
      <material
        name="">
        <color
          rgba="0.698039215686274 0.698039215686274 0.698039215686274 1" />
      </material>
    </visual>
    <collision>
      <origin
        xyz="0 0 0"
        rpy="0 0 0" />
      <geometry>
        <mesh
          filename="package://irobot_description/meshes/link_clip1_L.STL" />
      </geometry>
    </collision>
  </link>
  <joint
    name="joint_clip1_L"
    type="revolute">
    <origin
      xyz="0.018 0 0.077"
      rpy="1.5708 -1.5708 0" />
    <parent
      link="link7_L" />
    <child
      link="link_clip1_L" />
    <axis
      xyz="0 0 1" />
    <limit
      lower="-3"
      upper="3"
      effort="6"
      velocity="3" />
  </joint>
  <link
    name="link_clip2_L">
    <inertial>
      <origin
        xyz="0.0365169835636618 0.0209290671313445 -0.00105043811277783"
        rpy="0 0 0" />
      <mass
        value="0.049325480054978" />
      <inertia
        ixx="6.94591135342316E-05"
        ixy="-1.66142603365939E-05"
        ixz="-1.88959779772784E-06"
        iyy="0.000104034876104666"
        iyz="-1.0838794419823E-06"
        izz="5.7556875370648E-05" />
    </inertial>
    <visual>
      <origin
        xyz="0 0 0"
        rpy="0 0 0" />
      <geometry>
        <mesh
          filename="package://irobot_description/meshes/link_clip2_L.STL" />
      </geometry>
      <material
        name="">
        <color
          rgba="0.698039215686274 0.698039215686274 0.698039215686274 1" />
      </material>
    </visual>
    <collision>
      <origin
        xyz="0 0 0"
        rpy="0 0 0" />
      <geometry>
        <mesh
          filename="package://irobot_description/meshes/link_clip2_L.STL" />
      </geometry>
    </collision>
  </link>
  <joint
    name="joint_clip2_L"
    type="revolute">
    <origin
      xyz="-0.018 0 0.077"
      rpy="1.5708 -1.5708 0" />
    <parent
      link="link7_L" />
    <child
      link="link_clip2_L" />
    <axis
      xyz="0 0 1" />
    <limit
      lower="-3"
      upper="3"
      effort="6"
      velocity="3" />
  </joint>
  <link
    name="link_neck1">
    <inertial>
      <origin
        xyz="-7.1412E-08 0.0088561 -0.022837"
        rpy="0 0 0" />
      <mass
        value="0.26949" />
      <inertia
        ixx="1.8827E-05"
        ixy="7.6949E-11"
        ixz="1.2097E-10"
        iyy="1.7182E-05"
        iyz="-4.7921E-06"
        izz="2.0902E-05" />
    </inertial>
    <visual>
      <origin
        xyz="0 0 0"
        rpy="0 0 0" />
      <geometry>
        <mesh
          filename="package://irobot_description/meshes/link_neck1.STL" />
      </geometry>
      <material
        name="">
        <color
          rgba="0.75294 0.75294 0.75294 1" />
      </material>
    </visual>
    <collision>
      <origin
        xyz="0 0 0"
        rpy="0 0 0" />
      <geometry>
        <mesh
          filename="package://irobot_description/meshes/link_neck1.STL" />
      </geometry>
    </collision>
  </link>
  <joint
    name="joint_neck1"
    type="revolute">
    <origin
      xyz="0 0 1.462"
      rpy="0 0 0" />
    <parent
      link="base_link" />
    <child
      link="link_neck1" />
    <axis
      xyz="0 0 -1" />
    <limit
      lower="-3"
      upper="3"
      effort="6"
      velocity="3" />
  </joint>
  <link
    name="link_neck2">
    <inertial>
      <origin
        xyz="0.014571 -0.05844 0.005849"
        rpy="0 0 0" />
      <mass
        value="0.16341" />
      <inertia
        ixx="0.00055921"
        ixy="-7.0342E-05"
        ixz="1.3864E-05"
        iyy="0.00087714"
        iyz="-3.6644E-05"
        izz="0.0005704" />
    </inertial>
    <visual>
      <origin
        xyz="0 0 0"
        rpy="0 0 0" />
      <geometry>
        <mesh
          filename="package://irobot_description/meshes/link_neck2.STL" />
      </geometry>
      <material
        name="">
        <color
          rgba="0.69804 0.69804 0.69804 1" />
      </material>
    </visual>
    <collision>
      <origin
        xyz="0 0 0"
        rpy="0 0 0" />
      <geometry>
        <mesh
          filename="package://irobot_description/meshes/link_neck2.STL" />
      </geometry>
    </collision>
  </link>
  <joint
    name="joint_neck2"
    type="revolute">
    <origin
      xyz="0 0 0"
      rpy="-1.5708 0 0" />
    <parent
      link="link_neck1" />
    <child
      link="link_neck2" />
    <axis
      xyz="0 0 1" />
    <limit
      lower="-3"
      upper="3"
      effort="6"
      velocity="3" />
  </joint>
</robot>